[2025-06-22T18:33:02.821+0000] {taskinstance.py:1957} INFO - Dependencies all met for dep_context=non-requeueable deps ti=<TaskInstance: polygon_data_pipeline.create_tables scheduled__2025-06-22T12:00:00+00:00 [queued]>
[2025-06-22T18:33:02.825+0000] {taskinstance.py:1957} INFO - Dependencies all met for dep_context=requeueable deps ti=<TaskInstance: polygon_data_pipeline.create_tables scheduled__2025-06-22T12:00:00+00:00 [queued]>
[2025-06-22T18:33:02.826+0000] {taskinstance.py:2171} INFO - Starting attempt 1 of 3
[2025-06-22T18:33:02.833+0000] {taskinstance.py:2192} INFO - Executing <Task(PythonOperator): create_tables> on 2025-06-22 12:00:00+00:00
[2025-06-22T18:33:02.835+0000] {standard_task_runner.py:60} INFO - Started process 212 to run task
[2025-06-22T18:33:02.837+0000] {standard_task_runner.py:87} INFO - Running: ['***', 'tasks', 'run', 'polygon_data_pipeline', 'create_tables', 'scheduled__2025-06-22T12:00:00+00:00', '--job-id', '3', '--raw', '--subdir', 'DAGS_FOLDER/polygon_data_pipeline.py', '--cfg-path', '/tmp/tmpzrqvopba']
[2025-06-22T18:33:02.839+0000] {standard_task_runner.py:88} INFO - Job 3: Subtask create_tables
[2025-06-22T18:33:02.866+0000] {task_command.py:423} INFO - Running <TaskInstance: polygon_data_pipeline.create_tables scheduled__2025-06-22T12:00:00+00:00 [running]> on host 4a3c7287a072
[2025-06-22T18:33:02.907+0000] {taskinstance.py:2481} INFO - Exporting env vars: AIRFLOW_CTX_DAG_OWNER='quant-team' AIRFLOW_CTX_DAG_ID='polygon_data_pipeline' AIRFLOW_CTX_TASK_ID='create_tables' AIRFLOW_CTX_EXECUTION_DATE='2025-06-22T12:00:00+00:00' AIRFLOW_CTX_TRY_NUMBER='1' AIRFLOW_CTX_DAG_RUN_ID='scheduled__2025-06-22T12:00:00+00:00'
[2025-06-22T18:33:02.924+0000] {taskinstance.py:2699} ERROR - Task failed with exception
Traceback (most recent call last):
  File "/home/airflow/.local/lib/python3.11/site-packages/airflow/models/taskinstance.py", line 433, in _execute_task
    result = execute_callable(context=context, **execute_callable_kwargs)
             ^^^^^^^^^^^^^^^^^^^^^^^^^^^^^^^^^^^^^^^^^^^^^^^^^^^^^^^^^^^^
  File "/home/airflow/.local/lib/python3.11/site-packages/airflow/operators/python.py", line 199, in execute
    return_value = self.execute_callable()
                   ^^^^^^^^^^^^^^^^^^^^^^^
  File "/home/airflow/.local/lib/python3.11/site-packages/airflow/operators/python.py", line 216, in execute_callable
    return self.python_callable(*self.op_args, **self.op_kwargs)
           ^^^^^^^^^^^^^^^^^^^^^^^^^^^^^^^^^^^^^^^^^^^^^^^^^^^^^
  File "/opt/airflow/dags/polygon_data_pipeline.py", line 125, in create_market_data_tables
    conn.commit()
    ^^^^^^^^^^^
AttributeError: 'Connection' object has no attribute 'commit'
[2025-06-22T18:33:02.930+0000] {taskinstance.py:1138} INFO - Marking task as UP_FOR_RETRY. dag_id=polygon_data_pipeline, task_id=create_tables, execution_date=20250622T120000, start_date=20250622T183302, end_date=20250622T183302
[2025-06-22T18:33:02.935+0000] {standard_task_runner.py:107} ERROR - Failed to execute job 3 for task create_tables ('Connection' object has no attribute 'commit'; 212)
[2025-06-22T18:33:02.977+0000] {local_task_job_runner.py:234} INFO - Task exited with return code 1
[2025-06-22T18:33:02.992+0000] {taskinstance.py:3281} INFO - 0 downstream tasks scheduled from follow-on schedule check
